<?xml version="1.0"?>

<robot name="gripper" xmlns:xacro="http://www.ros.org/wiki/xacro">
    <xacro:include filename="$(find kuka_kr6_description)/urdf/common_constants/common_constants.xacro"/>
    
    <!--<link name="world"/>
    <joint name="world_joint" type="fixed">
        <parent link="world"/>
        <child link="hand"/>
        <origin xyz="0 0 0" rpy="0 0 0"/>
    </joint>-->

    <joint name="hand_joint" type="fixed">
        <parent link="tool0"/>
        <child link="hand"/>
        <origin xyz="0 0 0" rpy="0 0 0"/>
    </joint>

    <link name="hand">
        <visual>
            <origin xyz="0 0 0.02" rpy="0 0 0"/>
            <geometry>
                <box size="0.04 0.10 0.04"/>
            </geometry>
        </visual>
        <collision>
            <origin xyz="0 0 0.02" rpy="0 0 0"/>
            <geometry>
                <box size="0.04 0.10 0.04"/>
            </geometry>
        </collision>
    </link>

    <link name="left_finger">
        <visual>
            <origin xyz="0 0 0.02" rpy="0 0 0"/>
            <geometry>
                <mesh filename="package://franka_description/meshes/visual/finger.dae"/>
            </geometry>
        </visual>        
    </link>

    <link name="right_finger">
        <visual>
            <origin xyz="0 0 0.02" rpy="0 0 ${PI}"/>
            <geometry>
                <mesh filename="package://franka_description/meshes/visual/finger.dae"/>
            </geometry>
        </visual>
    </link>

    <joint name="left_finger_joint" type="prismatic">
        <parent link="hand"/>
        <child link="left_finger"/>
        <origin xyz="0 0 0.02" rpy="0 0 0"/>
        <axis xyz="0 1 0"/>
        <limit effort="20" lower="0.0" upper="0.04" velocity="0.2"/>
    </joint>

    <joint name="right_finger_joint" type="prismatic">
        <parent link="hand"/>
        <child link="right_finger"/>
        <origin xyz="0 0 0.02" rpy="0 0 0"/>
        <axis xyz="0 -1 0"/>
        <limit effort="20" lower="0.0" upper="0.4" velocity="0.2"/>
        <mimic joint="left_finger_joint" />
    </joint>

</robot>