<?xml version="1.0"?>

<robot name="kuka_kr6" xmlns:xacro="http://ros.org/wiki/xacro">
    <xacro:include filename="$(find kuka_kr6_description)/urdf/common_constants/common_constants.xacro"/>
    
    <xacro:macro name="default_inertial" params="mass">
        <inertial>
            <mass value="${mass}" />
            <inertia ixx="1.0" ixy="0.0" ixz="0.0"
                iyy="1.0" iyz="0.0"
                izz="1.0" />
        </inertial>
    </xacro:macro>

    <!--############################################################################################-->
        <!--Definition of robot's links-->
    <!--############################################################################################-->
    <link name="base_link">
        <xacro:default_inertial mass="1"/>
        <visual>
            <origin xyz="0 0 0" rpy="0 0 0"/>
            <geometry>
                <mesh filename="package://kuka_kr6_description/meshes/kr6r900sixx/visual/base_link.dae" />
            </geometry>
        </visual>
        <collision>
            <origin xyz="0 0 0" rpy="0 0 0"/>
            <geometry>
                <mesh filename="package://kuka_kr6_description/meshes/kr6r900sixx/collision/base_link.stl" />
            </geometry>
        </collision>
    </link>

    <link name="link_1">
        <xacro:default_inertial mass="1"/>
        <visual>
            <origin xyz="0 0 0" rpy="0 0 0"/>
            <geometry>
                <mesh filename="package://kuka_kr6_description/meshes/kr6r900sixx/visual/link_1.dae" />
            </geometry>
        </visual>
        <collision>
            <origin xyz="0 0 0" rpy="0 0 0"/>
            <geometry>
                <mesh filename="package://kuka_kr6_description/meshes/kr6r900sixx/collision/link_1.stl" />
            </geometry>
        </collision>
    </link>

    <link name="link_2">
        <xacro:default_inertial mass="1"/>
        <visual>
            <origin xyz="0 0 0" rpy="0 0 0"/>
            <geometry>
                <mesh filename="package://kuka_kr6_description/meshes/kr6r900sixx/visual/link_2.dae"/>
            </geometry>
        </visual>
            <collision>
            <origin xyz="0 0 0" rpy="0 0 0"/>
            <geometry>
                <mesh filename="package://kuka_kr6_description/meshes/kr6r900sixx/collision/link_2.stl" />
            </geometry>
        </collision>
    </link>

    <link name="link_3">
        <xacro:default_inertial mass="1"/>
        <visual>
            <origin xyz="0 0 0" rpy="0 0 0"/>
            <geometry>
                <mesh filename="package://kuka_kr6_description/meshes/kr6r900sixx/visual/link_3.dae" />
            </geometry>
        </visual>
        <collision>
            <origin xyz="0 0 0" rpy="0 0 0"/>
            <geometry>
                <mesh filename="package://kuka_kr6_description/meshes/kr6r900sixx/collision/link_3.stl" />
            </geometry>
        </collision>
    </link>

    <link name="link_4">
        <xacro:default_inertial mass="1"/>
        <visual>
            <origin xyz="0 0 0" rpy="0 0 0"/>
            <geometry>
                <mesh filename="package://kuka_kr6_description/meshes/kr6r900sixx/visual/link_4.dae" />
            </geometry>
        </visual>
        <collision>
            <origin xyz="0 0 0" rpy="0 0 0"/>
            <geometry>
                <mesh filename="package://kuka_kr6_description/meshes/kr6r900sixx/collision/link_4.stl" />
            </geometry>
        </collision>
    </link>

    <link name="link_5">
        <xacro:default_inertial mass="1"/>
        <visual>
            <origin xyz="0 0 0" rpy="0 0 0"/>
            <geometry>
                <mesh filename="package://kuka_kr6_description/meshes/kr6r900sixx/visual/link_5.dae" />
            </geometry>
        </visual>
        <collision>
            <origin xyz="0 0 0" rpy="0 0 0"/>
            <geometry>
                <mesh filename="package://kuka_kr6_description/meshes/kr6r900sixx/collision/link_5.stl" />
            </geometry>
        </collision>
    </link>

    <link name="link_6">
        <xacro:default_inertial mass="1"/>
        <visual>
            <origin xyz="0 0 0" rpy="0 0 0"/>
            <geometry>
                <mesh filename="package://kuka_kr6_description/meshes/kr6r900sixx/visual/link_6.dae" />
            </geometry>
        </visual>
        <collision>
            <origin xyz="0 0 0" rpy="0 0 0"/>
            <geometry>
                <mesh filename="package://kuka_kr6_description/meshes/kr6r900sixx/collision/link_6.stl" />
            </geometry>
        </collision>
    </link>

    <!-- This frame corresponds to the $FLANGE coordinate system in KUKA KRC controllers. -->
    <link name="tool0">
        <xacro:default_inertial mass = '0.000000001'/>
        <visual>
            <origin xyz = '0 0 0.05' rpy = '0 0 0'/>
            <geometry>
                <box size = "0.08 0.08 0.08" />
            </geometry>
        </visual>
    </link>


    <!--############################################################################################-->
        <!--Definition of robot's joints-->
    <!--############################################################################################-->
    <joint name="joint_a1" type="revolute">
        <origin xyz="0 0 0.400" rpy="0 0 0"/>
        <parent link="base_link"/>
        <child link="link_1"/>
        <axis xyz="0 0 -1"/>
        <limit effort="0" lower="${-DEG2RAD * 170}" upper="${DEG2RAD * 170}" velocity="${DEG2RAD * 360}"/>
    </joint>
    <joint name="joint_a2" type="revolute">
        <origin xyz="0.025 0 0" rpy="0 0 0"/>
        <parent link="link_1"/>
        <child link="link_2"/>
        <axis xyz="0 1 0"/>
        <!-- IMPORTANT: The original value here 'upper' is ${DEG2RAD * 45} -->
        <limit effort="0" lower="${-DEG2RAD * 190}" upper="${DEG2RAD * 75}" velocity="${DEG2RAD * 300}"/>
    </joint>
    <joint name="joint_a3" type="revolute">
        <origin xyz="0 0 0.455" rpy="0 0 0"/>
        <parent link="link_2"/>
        <child link="link_3"/>
        <axis xyz="0 1 0"/>
        <limit effort="0" lower="${-DEG2RAD * 120}" upper="${DEG2RAD * 156}" velocity="${DEG2RAD * 360}"/>
    </joint>
    <joint name="joint_a4" type="revolute">
        <origin xyz="0 0 0.035" rpy="0 0 0"/>
        <parent link="link_3"/>
        <child link="link_4"/>
        <axis xyz="-1 0 0"/>
        <limit effort="0" lower="${-DEG2RAD * 185}" upper="${DEG2RAD * 185}" velocity="${DEG2RAD * 381}"/>
    </joint>
    <joint name="joint_a5" type="revolute">
        <origin xyz="0.420 0 0" rpy="0 0 0"/>
        <parent link="link_4"/>
        <child link="link_5"/>
        <axis xyz="0 1 0"/>
        <limit effort="0" lower="${-DEG2RAD * 120}" upper="${DEG2RAD * 120}" velocity="${DEG2RAD * 388}"/>
    </joint>
    <joint name="joint_a6" type="revolute">
        <origin xyz="0.080 0 0" rpy="0 0 0"/>
        <parent link="link_5"/>
        <child link="link_6"/>
        <axis xyz="-1 0 0"/>
        <limit effort="0" lower="${-DEG2RAD * 350}" upper="${DEG2RAD * 350}" velocity="${DEG2RAD * 615}"/>
    </joint>
    <joint name="joint_a6-tool0" type="fixed">
        <parent link="link_6"/>
        <child link="tool0"/>
        <origin xyz="0 0 0" rpy="0 ${DEG2RAD * 90} 0"/>
    </joint>

</robot>